Workbook
Name Slicer_averageRating: #N/A
Name Slicer_genres: #N/A
Name Slicer_numVotes: #N/A
Name Slicer_releaseYear: #N/A
Name Slicer_title: #N/A

Sheet Raw data
A1: id | B1: title | C1: genres | D1: averageRating | E1: numVotes | F1: releaseYear
A2: tt2322441 | B2: Fifty Shades of Grey | C2: Drama, Romance, Thriller | D2: 4.2 | E2: 341094 | F2: 2015
A3: tt1259571 | B3: The Twilight Saga: New Moon | C3: Adventure, Drama, Fantasy | D3: 4.8 | E3: 304888 | F3: 2009
A4: tt0118688 | B4: Batman & Robin | C4: Action, Sci-Fi | D4: 3.8 | E4: 272072 | F4: 1997
A5: tt6027920 | B5: The Iron Throne | C5: Action, Adventure, Drama | D5: 4 | E5: 267936 | F5: 2019
A6: tt1325004 | B6: The Twilight Saga: Eclipse | C6: Action, Adventure, Drama | D6: 5.1 | E6: 265386 | F6: 2010
A7: tt1324999 | B7: The Twilight Saga: Breaking Dawn - Part 1 | C7: Adventure, Drama, Fantasy | D7: 4.9 | E7: 258475 | F7: 2011
A8: tt0949731 | B8: The Happening | C8: Adventure, Drama, Sci-Fi | D8: 5 | E8: 220066 | F8: 2008
A9: tt1606378 | B9: A Good Day to Die Hard | C9: Action, Thriller | D9: 5.2 | E9: 217048 | F9: 2013
A10: tt1815862 | B10: After Earth | C10: Action, Adventure, Sci-Fi | D10: 4.8 | E10: 211275 | F10: 2013
A11: tt10857160 | B11: She-Hulk: Attorney at Law | C11: Action, Adventure, Comedy | D11: 5.2 | E11: 195388 | F11: 2022
A12: tt1628841 | B12: Independence Day: Resurgence | C12: Action, Adventure, Sci-Fi | D12: 5.2 | E12: 192018 | F12: 2016
A13: tt10888594 | B13: Radhe | C13: Action, Crime, Thriller | D13: 1.9 | E13: 180273 | F13: 2021
... A460: tt23900194 | B460: Harry & Meghan | C460: Biography, Documentary | D460: 5.1 | E460: 23649 | F460: 2022
A461: tt3835080 | B461: 31 | C461: Horror, Thriller | D461: 5.1 | E461: 23633 | F461: 2016
A462: tt4667094 | B462: Fifty Shades of Black | C462: Comedy | D462: 3.5 | E462: 23615 | F462: 2016
A463: tt0430770 | B463: The Women | C463: Comedy, Drama | D463: 5 | E463: 23466 | F463: 2008
A464: tt5322012 | B464: Wish Upon | C464: Drama, Fantasy, Horror | D464: 5.1 | E464: 23465 | F464: 2017
A465: tt2578802 | B465: Remember the Monsters? | C465: Crime, Drama, Mystery | D465: 4.8 | E465: 23460 | F465: 2013
A466: tt0360556 | B466: Fahrenheit 451 | C466: Drama, Sci-Fi, Thriller | D466: 5 | E466: 23421 | F466: 2018
A467: tt2974918 | B467: Alvin and the Chipmunks: The Road Chip | C467: Adventure, Comedy, Family | D467: 4.9 | E467: 23360 | F467: 2015
A468: tt15387022 | B468: Revenge/Justice | C468: Action, Adventure, Drama | D468: 5.1 | E468: 23343 | F468: 2024
A469: tt12783454 | B469: The Kissing Booth 3 | C469: Comedy, Romance | D469: 4.8 | E469: 23297 | F469: 2021
A470: tt1373215 | B470: Recep Ivedik 2 | C470: Comedy | D470: 4.5 | E470: 23286 | F470: 2009
A471: tt6950476 | B471: Tejas | C471: Action, Drama, Thriller | D471: 4.4 | E471: 23267 | F471: 2023
A472: tt5997666 | B472: Jab Harry Met Sejal | C472: Comedy, Drama, Romance | D472: 5.1 | E472: 23205 | F472: 2017
A473: tt6910020 | B473: Nothing to Lose | C473: Biography, Drama | D473: 2.4 | E473: 23140 | F473: 2018
... A784: tt15387058 | B784: Choice | C784: Action, Adventure, Drama | D784: 4.6 | E784: 12654 | F784: 2024
A785: tt1712159 | B785: 40858 | C785: Horror, Mystery, Thriller | D785: 3.9 | E785: 12653 | F785: 2011
A786: tt2091478 | B786: Air | C786: Drama, Sci-Fi, Thriller | D786: 5.1 | E786: 12651 | F786: 2015
A787: tt0110647 | B787: The NeverEnding Story III | C787: Adventure, Comedy, Family | D787: 3.2 | E787: 12633 | F787: 1994
A788: tt3053228 | B788: Day of the Dead: Bloodline | C788: Action, Drama, Horror | D788: 3.5 | E788: 12616 | F788: 2017
A789: tt0089280 | B789: Hobgoblins | C789: Comedy, Horror, Sci-Fi | D789: 2.2 | E789: 12606 | F789: 1988
A790: tt1403988 | B790: The Romantics | C790: Comedy, Drama, Romance | D790: 5 | E790: 12596 | F790: 2010
A791: tt5884234 | B791: First Kill | C791: Action, Thriller | D791: 5 | E791: 12582 | F791: 2017
A792: tt1780762 | B792: Aftershock | C792: Action, Adventure, Horror | D792: 4.8 | E792: 12573 | F792: 2012
A793: tt1552211 | B793: The Last Days of American Crime | C793: Action, Crime, Drama | D793: 3.8 | E793: 12566 | F793: 2020
A794: tt0462395 | B794: Larry the Cable Guy: Health Inspector | C794: Comedy, Romance | D794: 3.5 | E794: 12561 | F794: 2006
A795: tt3322892 | B795: XX | C795: Horror | D795: 4.6 | E795: 12545 | F795: 2017
A796: tt0118539 | B796: 3 Ninjas: High Noon at Mega Mountain | C796: Action, Adventure, Comedy | D796: 3 | E796: 12537 | F796: 1998
...

Sheet INDEX
B3: CHAPTERS | C3: FUNCTIONS USED
B4: 1 | C4: SUM, AVERAGE, MIN, MAX, COUNT, COUNTA
B5: 2 | C5: RANK.EQ, AVERAGEIF, COUNT IF, SUM IF,LARGE, SMALL,STANDARD DEVIATION, MEDIAN,MODE
B6: 3 | C6: COUNTIF, SUMIFS,ROUND
B7: 3.1 | C7: STOCKS(OPEN, VOLUME, HIGH LOW CHARTS)
B8: 4 | C8: CONDITIONAL FORMATTING, IF, OR, AND, NOT
B9: 5 | C9: VLOOKUP, UNIQUE, COUNTIF, SUMIFS, INDEX MATCH
B10: 6 | C10: IPMT, PPMT
B11: 7 | C11: SLICERS, CONCAT,TRIM
B12: 7.1 | C12: PIVOT TABLES
B13: 8 | C13: BREAK EVEN ANALYSIS, DATA TABLE
B14: 9 | C14: GOAL SEEK

Sheet Chapter - 1
A1: id | B1: title | C1: genres | D1: averageRating | E1: numVotes | F1: releaseYear
A2: tt2322441 | B2: Fifty Shades of Grey | C2: Drama, Romance, Thriller | D2: 4.2 | E2: 341094 | F2: 2015 | H2: Chapter 1: Basic Formula's
A3: tt1259571 | B3: The Twilight Saga: New Moon | C3: Adventure, Drama, Fantasy | D3: 4.8 | E3: 304888 | F3: 2009 | H3: Sum | I3: Total Numbe of Votes | J3: =SUM(E2:E1001) -> 34265064
A4: tt0118688 | B4: Batman & Robin | C4: Action, Sci-Fi | D4: 3.8 | E4: 272072 | F4: 1997 | H4: Average | I4: Average of NumVotes | J4: =AVERAGE(E2:E1001) -> 34265.064
A5: tt6027920 | B5: The Iron Throne | C5: Action, Adventure, Drama | D5: 4 | E5: 267936 | F5: 2019 | H5: Minimum | I5: Minimum Rating | J5: =MIN(D2:D1001) -> 1
A6: tt1325004 | B6: The Twilight Saga: Eclipse | C6: Action, Adventure, Drama | D6: 5.1 | E6: 265386 | F6: 2010 | H6: Mximum | I6: Maximum Rating | J6: =MAX(D2:D1001) -> 5.2
A7: tt1324999 | B7: The Twilight Saga: Breaking Dawn - Part 1 | C7: Adventure, Drama, Fantasy | D7: 4.9 | E7: 258475 | F7: 2011 | H7: Count | I7: ReleaseYear | J7: =COUNT(F2:F1001) -> 1000
A8: tt0949731 | B8: The Happening | C8: Adventure, Drama, Sci-Fi | D8: 5 | E8: 220066 | F8: 2008 | H8: CountA | I8: Title | J8: =COUNTA(B2:B1001) -> 1000
A9: tt1606378 | B9: A Good Day to Die Hard | C9: Action, Thriller | D9: 5.2 | E9: 217048 | F9: 2013
A10: tt1815862 | B10: After Earth | C10: Action, Adventure, Sci-Fi | D10: 4.8 | E10: 211275 | F10: 2013
A11: tt10857160 | B11: She-Hulk: Attorney at Law | C11: Action, Adventure, Comedy | D11: 5.2 | E11: 195388 | F11: 2022
A12: tt1628841 | B12: Independence Day: Resurgence | C12: Action, Adventure, Sci-Fi | D12: 5.2 | E12: 192018 | F12: 2016
A13: tt10888594 | B13: Radhe | C13: Action, Crime, Thriller | D13: 1.9 | E13: 180273 | F13: 2021
A14: tt1502712 | B14: Fantastic Four | C14: Action, Adventure, Sci-Fi | D14: 4.3 | E14: 179961 | F14: 2015
A15: tt0938283 | B15: The Last Airbender | C15: Action, Adventure, Family | D15: 4 | E15: 176827 | F15: 2010
A16: tt0859163 | B16: The Mummy: Tomb of the Dragon Emperor | C16: Action, Adventure, Fantasy | D16: 5.2 | E16: 173199 | F16: 2008
A17: tt3371366 | B17: Transformers: The Last Knight | C17: Action, Adventure, Sci-Fi | D17: 5.2 | E17: 172818 | F17: 2017
A18: tt0120891 | B18: Wild Wild West | C18: Action, Comedy, Sci-Fi | D18: 4.9 | E18: 168977 | F18: 1999
A19: tt5433138 | B19: F9: The Fast Saga | C19: Action, Crime, Thriller | D19: 5.2 | E19: 166852 | F19: 2021
A20: tt5108870 | B20: Morbius | C20: Action, Adventure, Horror | D20: 5.1 | E20: 158856 | F20: 2022
... A460: tt23900194 | B460: Harry & Meghan | C460: Biography, Documentary | D460: 5.1 | E460: 23649 | F460: 2022
A461: tt3835080 | B461: 31 | C461: Horror, Thriller | D461: 5.1 | E461: 23633 | F461: 2016
A462: tt4667094 | B462: Fifty Shades of Black | C462: Comedy | D462: 3.5 | E462: 23615 | F462: 2016
A463: tt0430770 | B463: The Women | C463: Comedy, Drama | D463: 5 | E463: 23466 | F463: 2008
A464: tt5322012 | B464: Wish Upon | C464: Drama, Fantasy, Horror | D464: 5.1 | E464: 23465 | F464: 2017
A465: tt2578802 | B465: Remember the Monsters? | C465: Crime, Drama, Mystery | D465: 4.8 | E465: 23460 | F465: 2013
A466: tt0360556 | B466: Fahrenheit 451 | C466: Drama, Sci-Fi, Thriller | D466: 5 | E466: 23421 | F466: 2018
A467: tt2974918 | B467: Alvin and the Chipmunks: The Road Chip | C467: Adventure, Comedy, Family | D467: 4.9 | E467: 23360 | F467: 2015
A468: tt15387022 | B468: Revenge/Justice | C468: Action, Adventure, Drama | D468: 5.1 | E468: 23343 | F468: 2024
A469: tt12783454 | B469: The Kissing Booth 3 | C469: Comedy, Romance | D469: 4.8 | E469: 23297 | F469: 2021
A470: tt1373215 | B470: Recep Ivedik 2 | C470: Comedy | D470: 4.5 | E470: 23286 | F470: 2009
A471: tt6950476 | B471: Tejas | C471: Action, Drama, Thriller | D471: 4.4 | E471: 23267 | F471: 2023
A472: tt5997666 | B472: Jab Harry Met Sejal | C472: Comedy, Drama, Romance | D472: 5.1 | E472: 23205 | F472: 2017
A473: tt6910020 | B473: Nothing to Lose | C473: Biography, Drama | D473: 2.4 | E473: 23140 | F473: 2018
... A784: tt15387058 | B784: Choice | C784: Action, Adventure, Drama | D784: 4.6 | E784: 12654 | F784: 2024
A785: tt1712159 | B785: 40858 | C785: Horror, Mystery, Thriller | D785: 3.9 | E785: 12653 | F785: 2011
A786: tt2091478 | B786: Air | C786: Drama, Sci-Fi, Thriller | D786: 5.1 | E786: 12651 | F786: 2015
A787: tt0110647 | B787: The NeverEnding Story III | C787: Adventure, Comedy, Family | D787: 3.2 | E787: 12633 | F787: 1994
A788: tt3053228 | B788: Day of the Dead: Bloodline | C788: Action, Drama, Horror | D788: 3.5 | E788: 12616 | F788: 2017
A789: tt0089280 | B789: Hobgoblins | C789: Comedy, Horror, Sci-Fi | D789: 2.2 | E789: 12606 | F789: 1988
...

Sheet Chapter - 2
A1: title | B1: genres | C1: averageRating | D1: Ranking on AvgRating | E1: numVotes | F1: releaseYear
A2: Under Paris | B2: Action, Drama, Horror | C2: 5.2 | D2: =_xlfn.RANK.EQ(C2, C2:C1001) -> 1 | E2: 32479 | F2: 2024
A3: Uglies | B3: Action, Adventure, Drama | C3: 4.7 | D3: =_xlfn.RANK.EQ(C3, C3:C1002) -> 423 | E3: 25779 | F3: 2024 | H3: Chapter 2: Basic Formula's
A4: Trigger Warning | B4: Action, Crime, Thriller | C4: 4.6 | D4: =_xlfn.RANK.EQ(C4, C4:C1003) -> 498 | E4: 17570 | F4: 2024 | H4: AVERAGEIF | I4: Average rating for movies in "Action" genre | J4: =AVERAGEIF(B2:B1001, "Action", C2:C1001) -> 4.25
A5: The Tearsmith | B5: Drama, Fantasy, Romance | C5: 5.1 | D5: =_xlfn.RANK.EQ(C5, C5:C1004) -> 48 | E5: 10227 | F5: 2024 | H5: SUMIF | I5: Sum of numVotes for movies with averageRating > 5.1 | J5: =SUMIF(C2:C1001, ">5.1", E2:E1001) -> 3767189
A6: The Strangers: Chapter 1 | B6: Horror | C6: 4.6 | D6: =_xlfn.RANK.EQ(C6, C6:C1005) -> 497 | E6: 19176 | F6: 2024 | H6: MEDIAN | I6: AverageRating | J6: =MEDIAN(C2:C1001) -> 4.6
A7: The Platform 2 | B7: Horror, Sci-Fi, Thriller | C7: 5 | D7: =_xlfn.RANK.EQ(C7, C7:C1006) -> 170 | E7: 29234 | F7: 2024 | H7: MODE | I7: AverageRating | J7: =MODE(C2:C1001) -> 5.1
A8: The Deliverance | B8: Horror, Thriller | C8: 5.1 | D8: =_xlfn.RANK.EQ(C8, C8:C1007) -> 48 | E8: 19367 | F8: 2024 | H8: STANDARD DEVIATION | I8: AverageRating | J8: =STDEV( C2:C1001) -> 0.89266525
A9: The Crow | B9: Action, Crime, Fantasy | C9: 4.7 | D9: =_xlfn.RANK.EQ(C9, C9:C1008) -> 420 | E9: 24427 | F9: 2024 | H9: COUNTIF | I9: Movies with averageRating > 4.4 | J9: =COUNTIF(C2:C1001, ">4.4") -> 610
A10: The American Society of Magical Negroes | B10: Comedy, Fantasy | C10: 3.6 | D10: =_xlfn.RANK.EQ(C10, C10:C1009) -> 820 | E10: 10937 | F10: 2024 | H10: COUNTIFS | I10: Movies with averageRating > 4.4 and numVotes > 20,000 | J10: =COUNTIFS(C2:C1001, ">4.4", E2:E1001, ">20000") -> 343
A11: The Acolyte | B11: Action, Adventure, Drama | C11: 4.1 | D11: =_xlfn.RANK.EQ(C11, C11:C1010) -> 714 | E11: 124735 | F11: 2024 | H11: LARGE | I11: 1st largest value in the numVotes column | J11: =LARGE(E2:E1001, 1) -> 341094
A12: Teach/Corrupt | B12: Action, Adventure, Drama | C12: 5.1 | D12: =_xlfn.RANK.EQ(C12, C12:C1011) -> 48 | E12: 12964 | F12: 2024 | H12: LARGE | I12: 2nd largest value in the numVotes column | J12: =LARGE(E2:E1001, 2) -> 304888
A13: Tarot | B13: Horror | C13: 4.8 | D13: =_xlfn.RANK.EQ(C13, C13:C1012) -> 324 | E13: 25522 | F13: 2024 | H13: SMALL | I13: 1st smallest value in the averageRating column | J13: =SMALL(E2:E1001, 1) -> 10007
A14: Revenge/Justice | B14: Action, Adventure, Drama | C14: 5.1 | D14: =_xlfn.RANK.EQ(C14, C14:C1013) -> 48 | E14: 23343 | F14: 2024 | H14: SMALL | I14: 2nd smallest value in the averageRating column | J14: =SMALL(E2:E1001, 2) -> 10015
A15: Now or Never! | B15: Adventure, Biography, Drama | C15: 2 | D15: =_xlfn.RANK.EQ(C15, C15:C1014) -> 947 | E15: 16400 | F15: 2024
A16: Night Swim | B16: Horror, Thriller | C16: 4.7 | D16: =_xlfn.RANK.EQ(C16, C16:C1015) -> 417 | E16: 25006 | F16: 2024 | H16: How many titles are there in a releaseYear and averageRating of each title
A17: Mother of the Bride | B17: Comedy, Drama, Romance | C17: 4.8 | D17: =_xlfn.RANK.EQ(C17, C17:C1016) -> 323 | E17: 15187 | F17: 2024 | H17: Release Year | I17: Count of Titles in the Year 2015 - 2024 | J17: Average Rating
A18: Megalopolis | B18: Drama, Fantasy, Sci-Fi | C18: 5.1 | D18: =_xlfn.RANK.EQ(C18, C18:C1017) -> 48 | E18: 17457 | F18: 2024 | H18: 2015 | I18: =COUNTIF(F:F, H18) -> 35 | J18: =ROUND(AVERAGEIF(F:F, H18, C:C), 1) -> 4.4
A19: Martin | B19: Action, Drama, Thriller | C19: 4.5 | D19: =_xlfn.RANK.EQ(C19, C19:C1018) -> 551 | E19: 34529 | F19: 2024 | H19: 2016 | I19: =COUNTIF(F:F, H19) -> 29 | J19: =ROUND(AVERAGEIF(F:F, H19, C:C), 1) -> 4.5
A20: Madame Web | B20: Action, Adventure, Sci-Fi | C20: 4 | D20: =_xlfn.RANK.EQ(C20, C20:C1019) -> 728 | E20: 91349 | F20: 2024 | H20: 2017 | I20: =COUNTIF(F:F, H20) -> 39 | J20: =ROUND(AVERAGEIF(F:F, H20, C:C), 1) -> 4.3
A21: Indian Police Force | B21: Action, Crime, Drama | C21: 4.9 | D21: =_xlfn.RANK.EQ(C21, C21:C1020) -> 248 | E21: 58338 | F21: 2024 | H21: 2018 | I21: =COUNTIF(F:F, H21) -> 37 | J21: =ROUND(AVERAGEIF(F:F, H21, C:C), 1) -> 4.2
A22: Indian 2 | B22: Action, Drama, Thriller | C22: 3.9 | D22: =_xlfn.RANK.EQ(C22, C22:C1021) -> 747 | E22: 15666 | F22: 2024 | H22: 2019 | I22: =COUNTIF(F:F, H22) -> 37 | J22: =ROUND(AVERAGEIF(F:F, H22, C:C), 1) -> 4.2
A23: Imaginary | B23: Horror, Mystery, Thriller | C23: 4.7 | D23: =_xlfn.RANK.EQ(C23, C23:C1022) -> 414 | E23: 15023 | F23: 2024 | H23: 2020 | I23: =COUNTIF(F:F, H23) -> 47 | J23: =ROUND(AVERAGEIF(F:F, H23, C:C), 1) -> 4.1
A24: Destiny | B24: Action, Adventure, Drama | C24: 3.7 | D24: =_xlfn.RANK.EQ(C24, C24:C1023) -> 793 | E24: 25920 | F24: 2024 | H24: 2021 | I24: =COUNTIF(F:F, H24) -> 41 | J24: =ROUND(AVERAGEIF(F:F, H24, C:C), 1) -> 4.1
A25: Day | B25: Action, Adventure, Drama | C25: 4.8 | D25: =_xlfn.RANK.EQ(C25, C25:C1024) -> 321 | E25: 17929 | F25: 2024 | H25: 2022 | I25: =COUNTIF(F:F, H25) -> 46 | J25: =ROUND(AVERAGEIF(F:F, H25, C:C), 1) -> 4.2
A26: Choice | B26: Action, Adventure, Drama | C26: 4.6 | D26: =_xlfn.RANK.EQ(C26, C26:C1025) -> 485 | E26: 12654 | F26: 2024 | H26: 2023 | I26: =COUNTIF(F:F, H26) -> 33 | J26: =ROUND(AVERAGEIF(F:F, H26, C:C), 1) -> 4
A27: Borderlands | B27: Action, Adventure, Comedy | C27: 4.6 | D27: =_xlfn.RANK.EQ(C27, C27:C1026) -> 485 | E27: 31263 | F27: 2024 | H27: 2024 | I27: =COUNTIF(F:F, H27) -> 29 | J27: =ROUND(AVERAGEIF(F:F, H27, C:C), 1) -> 4.5
A28: Bhool Bhulaiyaa 3 | B28: Comedy, Horror | C28: 5 | D28: =_xlfn.RANK.EQ(C28, C28:C1027) -> 166 | E28: 30918 | F28: 2024
A29: Bade Miyan Chote Miyan | B29: Action, Adventure, Sci-Fi | C29: 3.9 | D29: =_xlfn.RANK.EQ(C29, C29:C1028) -> 742 | E29: 38451 | F29: 2024
A30: Bad Newz | B30: Comedy, Romance | C30: 4.9 | D30: =_xlfn.RANK.EQ(C30, C30:C1029) -> 247 | E30: 25175 | F30: 2024
A31: Yaariyan 2 | B31: Comedy, Drama, Musical | C31: 5.1 | D31: =_xlfn.RANK.EQ(C31, C31:C1030) -> 48 | E31: 11639 | F31: 2023
A32: Winnie-the-Pooh: Blood and Honey | B32: Horror | C32: 2.9 | D32: =_xlfn.RANK.EQ(C32, C32:C1031) -> 879 | E32: 31766 | F32: 2023
A33: Velma | B33: Adventure, Animation, Comedy | C33: 1.6 | D33: =_xlfn.RANK.EQ(C33, C33:C1032) -> 947 | E33: 79558 | F33: 2023
A34: The Strays | B34: Drama, Mystery, Thriller | C34: 4.9 | D34: =_xlfn.RANK.EQ(C34, C34:C1033) -> 246 | E34: 12479 | F34: 2023
A35: The Last Pharaoh | B35: Documentary, Drama, History | C35: 1.1 | D35: =_xlfn.RANK.EQ(C35, C35:C1034) -> 962 | E35: 12019 | F35: 2023
A36: The Idol | B36: Drama, Music | C36: 4.4 | D36: =_xlfn.RANK.EQ(C36, C36:C1035) -> 587 | E36: 112636 | F36: 2023
A37: The Holy Trinity | B37: Horror | C37: 3.2 | D37: =_xlfn.RANK.EQ(C37, C37:C1036) -> 854 | E37: 12288 | F37: 2023
A38: The Expendables 4 | B38: Action, Adventure, Thriller | C38: 4.8 | D38: =_xlfn.RANK.EQ(C38, C38:C1037) -> 317 | E38: 45770 | F38: 2023
A39: The Exorcist: Believer | B39: Horror | C39: 4.8 | D39: =_xlfn.RANK.EQ(C39, C39:C1038) -> 317 | E39: 44700 | F39: 2023
... A196: 321 Action | B196: Drama | C196: 1 | D196: =_xlfn.RANK.EQ(C196, C196:C1195) -> 804 | E196: 10215 | F196: 2020
...

Sheet Chapter - 3
A1: Release Year | B1: Count OF Titles YearWise | C1: Sum of NumVotes | D1: Avg of AverageRating | E1: Rating Trend
A2: {=_xlfn.UNIQUE('Chapter - 2'!F2:F1001)} -> 2024 | B2: =COUNTIF('Chapter - 1'!F:F, A2) -> 29 | C2: =SUMIF('Chapter - 1'!F:F, A2,'Chapter - 1'!E:E) -> 847025 | D2: =ROUND(AVERAGEIF('Chapter - 1'!F:F, A2,'Chapter - 1'!D:D), 1) -> 4.5
A3: 2023 | B3: =COUNTIF('Chapter - 1'!F:F, A3) -> 33 | C3: =SUMIF('Chapter - 1'!F:F, A3,'Chapter - 1'!E:E) -> 1065820 | D3: =ROUND(AVERAGEIF('Chapter - 1'!F:F, A3,'Chapter - 1'!D:D), 1) -> 4
A4: 2022 | B4: =COUNTIF('Chapter - 1'!F:F, A4) -> 46 | C4: =SUMIF('Chapter - 1'!F:F, A4,'Chapter - 1'!E:E) -> 1581172 | D4: =ROUND(AVERAGEIF('Chapter - 1'!F:F, A4,'Chapter - 1'!D:D), 1) -> 4.2
A5: 2021 | B5: =COUNTIF('Chapter - 1'!F:F, A5) -> 41 | C5: =SUMIF('Chapter - 1'!F:F, A5,'Chapter - 1'!E:E) -> 1314706 | D5: =ROUND(AVERAGEIF('Chapter - 1'!F:F, A5,'Chapter - 1'!D:D), 1) -> 4.1
A6: 2020 | B6: =COUNTIF('Chapter - 1'!F:F, A6) -> 47 | C6: =SUMIF('Chapter - 1'!F:F, A6,'Chapter - 1'!E:E) -> 1145761 | D6: =ROUND(AVERAGEIF('Chapter - 1'!F:F, A6,'Chapter - 1'!D:D), 1) -> 4.1
A7: 2019 | B7: =COUNTIF('Chapter - 1'!F:F, A7) -> 37 | C7: =SUMIF('Chapter - 1'!F:F, A7,'Chapter - 1'!E:E) -> 1045626 | D7: =ROUND(AVERAGEIF('Chapter - 1'!F:F, A7,'Chapter - 1'!D:D), 1) -> 4.2
A8: 2018 | B8: =COUNTIF('Chapter - 1'!F:F, A8) -> 37 | C8: =SUMIF('Chapter - 1'!F:F, A8,'Chapter - 1'!E:E) -> 991257 | D8: =ROUND(AVERAGEIF('Chapter - 1'!F:F, A8,'Chapter - 1'!D:D), 1) -> 4.2
A9: 2017 | B9: =COUNTIF('Chapter - 1'!F:F, A9) -> 39 | C9: =SUMIF('Chapter - 1'!F:F, A9,'Chapter - 1'!E:E) -> 1400603 | D9: =ROUND(AVERAGEIF('Chapter - 1'!F:F, A9,'Chapter - 1'!D:D), 1) -> 4.3
A10: 2016 | B10: =COUNTIF('Chapter - 1'!F:F, A10) -> 29 | C10: =SUMIF('Chapter - 1'!F:F, A10,'Chapter - 1'!E:E) -> 944673 | D10: =ROUND(AVERAGEIF('Chapter - 1'!F:F, A10,'Chapter - 1'!D:D), 1) -> 4.5
A11: 2015 | B11: =COUNTIF('Chapter - 1'!F:F, A11) -> 35 | C11: =SUMIF('Chapter - 1'!F:F, A11,'Chapter - 1'!E:E) -> 1477662 | D11: =ROUND(AVERAGEIF('Chapter - 1'!F:F, A11,'Chapter - 1'!D:D), 1) -> 4.4
A12: 2014 | B12: =COUNTIF('Chapter - 1'!F:F, A12) -> 38 | C12: =SUMIF('Chapter - 1'!F:F, A12,'Chapter - 1'!E:E) -> 1130910 | D12: =ROUND(AVERAGEIF('Chapter - 1'!F:F, A12,'Chapter - 1'!D:D), 1) -> 4.5
A13: 2013 | B13: =COUNTIF('Chapter - 1'!F:F, A13) -> 26 | C13: =SUMIF('Chapter - 1'!F:F, A13,'Chapter - 1'!E:E) -> 1106743 | D13: =ROUND(AVERAGEIF('Chapter - 1'!F:F, A13,'Chapter - 1'!D:D), 1) -> 4.4
A14: 2012 | B14: =COUNTIF('Chapter - 1'!F:F, A14) -> 30 | C14: =SUMIF('Chapter - 1'!F:F, A14,'Chapter - 1'!E:E) -> 886017 | D14: =ROUND(AVERAGEIF('Chapter - 1'!F:F, A14,'Chapter - 1'!D:D), 1) -> 4.5
... A55: 1957 | B55: =COUNTIF('Chapter - 1'!F:F, A55) -> 1 | C55: =SUMIF('Chapter - 1'!F:F, A55,'Chapter - 1'!E:E) -> 41105 | D55: =ROUND(AVERAGEIF('Chapter - 1'!F:F, A55,'Chapter - 1'!D:D), 1) -> 3.9

Sheet Chapter-3 Stocks
A1: Relating Movie Ratings to Stock Performance of Movie Studios
A2: Release Date | B2: Title | C2: Rating | D2: Stock Open | E2: Stock High | F2: Stock Low | G2: Stock Close | H2: Volume
A3: 45467 | B3: The Acolyte | C3: 8.1 | D3: 128.1 | E3: 133.5 | F3: 127.5 | G3: 130 | H3: 10000000
A4: 45468 | B4: The Acolyte | C4: 8.1 | D4: 130 | E4: 134 | F4: 129 | G4: 133 | H4: 12000000
A5: 45469 | B5: The Acolyte | C5: 8.1 | D5: 133 | E5: 136 | F5: 131 | G5: 134.5 | H5: 11000000
A6: 45470 | B6: The Acolyte | C6: 8.1 | D6: 134.5 | E6: 138 | F6: 132.5 | G6: 137 | H6: 9500000
A7: 45471 | B7: The Acolyte | C7: 8.1 | D7: 137 | E7: 140 | F7: 136.5 | G7: 139.5 | H7: 13000000
B9: Stock Price : Open High Low Close Chart | J9: Stock Price: Volume High Low Close Chart | R9: Stock Price : High Low Close Chart

Sheet Chapter - 4
A1: id | B1: title | C1: genres | D1: averageRating | E1: numVotes | F1: releaseYear | G1: AND | H1: OR | I1: NOT | J1: IF
A2: tt13964390 | B2: Under Paris | C2: Action, Drama, Horror | D2: 5.2 | E2: 32479 | F2: 2024 | G2: =IF(AND(D2>5, E2>1000), "Popular", "Not Popular") -> Popular | H2: =IF(OR(ISNUMBER(SEARCH("Action", C2)), ISNUMBER(SEARCH("Drama", C2))), "Action or Drama", IF(OR(ISNUMBER(SEARCH("Horror", C2)), ISNUMBER(SEARCH("Thriller", C2))), "Horror or Thriller", "Other")) -> Action or Drama | I2: =IF(NOT(ISNUMBER(SEARCH("Comedy", C2))), "Not Comedy", "Comedy") -> Not Comedy | J2: =IF(F2>2020, "Recent", "Old") -> Recent | L2: Condition | M2: Comments
A3: tt13186604 | B3: Uglies | C3: Action, Adventure, Drama | D3: 4.7 | E3: 25779 | F3: 2024 | G3: =IF(AND(D3>5, E3>1000), "Popular", "Not Popular") -> Not Popular | H3: =IF(OR(ISNUMBER(SEARCH("Action", C3)), ISNUMBER(SEARCH("Drama", C3))), "Action or Drama", IF(OR(ISNUMBER(SEARCH("Horror", C3)), ISNUMBER(SEARCH("Thriller", C3))), "Horror or Thriller", "Other")) -> Action or Drama | I3: =IF(NOT(ISNUMBER(SEARCH("Comedy", C3))), "Not Comedy", "Comedy") -> Not Comedy | J3: =IF(F3>2020, "Recent", "Old") -> Recent | L3: AND | M3: This formula will label movies as "Popular" if both the average rating is greater than 5 and the number of votes exceeds 1000.
A4: tt5834874 | B4: Trigger Warning | C4: Action, Crime, Thriller | D4: 4.6 | E4: 17570 | F4: 2024 | G4: =IF(AND(D4>5, E4>1000), "Popular", "Not Popular") -> Not Popular | H4: =IF(OR(ISNUMBER(SEARCH("Action", C4)), ISNUMBER(SEARCH("Drama", C4))), "Action or Drama", IF(OR(ISNUMBER(SEARCH("Horror", C4)), ISNUMBER(SEARCH("Thriller", C4))), "Horror or Thriller", "Other")) -> Action or Drama | I4: =IF(NOT(ISNUMBER(SEARCH("Comedy", C4))), "Not Comedy", "Comedy") -> Not Comedy | J4: =IF(F4>2020, "Recent", "Old") -> Recent | L4: OR | M4: Condition based on the genres to check if a movie's genre matches any of the given categories, like "Action," "Drama," "Horror," etc.
A5: tt29114029 | B5: The Tearsmith | C5: Drama, Fantasy, Romance | D5: 5.1 | E5: 10227 | F5: 2024 | G5: =IF(AND(D5>5, E5>1000), "Popular", "Not Popular") -> Popular | H5: =IF(OR(ISNUMBER(SEARCH("Action", C5)), ISNUMBER(SEARCH("Drama", C5))), "Action or Drama", IF(OR(ISNUMBER(SEARCH("Horror", C5)), ISNUMBER(SEARCH("Thriller", C5))), "Horror or Thriller", "Other")) -> Action or Drama | I5: =IF(NOT(ISNUMBER(SEARCH("Comedy", C5))), "Not Comedy", "Comedy") -> Not Comedy | J5: =IF(F5>2020, "Recent", "Old") -> Recent | L5: NOT | M5: Categorize movies as "Not Comedy" if genre does not include "Comedy" and categorize them as "Comedy" if the genre contains "Comedy."
A6: tt22050754 | B6: The Strangers: Chapter 1 | C6: Horror | D6: 4.6 | E6: 19176 | F6: 2024 | G6: =IF(AND(D6>5, E6>1000), "Popular", "Not Popular") -> Not Popular | H6: =IF(OR(ISNUMBER(SEARCH("Action", C6)), ISNUMBER(SEARCH("Drama", C6))), "Action or Drama", IF(OR(ISNUMBER(SEARCH("Horror", C6)), ISNUMBER(SEARCH("Thriller", C6))), "Horror or Thriller", "Other")) -> Horror or Thriller | I6: =IF(NOT(ISNUMBER(SEARCH("Comedy", C6))), "Not Comedy", "Comedy") -> Not Comedy | J6: =IF(F6>2020, "Recent", "Old") -> Recent | L6: IF | M6: This will label movies as "Recent" if the release year is after 2020, otherwise as "Old".
A7: tt27729779 | B7: The Platform 2 | C7: Horror, Sci-Fi, Thriller | D7: 5 | E7: 29234 | F7: 2024 | G7: =IF(AND(D7>5, E7>1000), "Popular", "Not Popular") -> Not Popular | H7: =IF(OR(ISNUMBER(SEARCH("Action", C7)), ISNUMBER(SEARCH("Drama", C7))), "Action or Drama", IF(OR(ISNUMBER(SEARCH("Horror", C7)), ISNUMBER(SEARCH("Thriller", C7))), "Horror or Thriller", "Other")) -> Horror or Thriller | I7: =IF(NOT(ISNUMBER(SEARCH("Comedy", C7))), "Not Comedy", "Comedy") -> Not Comedy | J7: =IF(F7>2020, "Recent", "Old") -> Recent
A8: tt4196566 | B8: The Deliverance | C8: Horror, Thriller | D8: 5.1 | E8: 19367 | F8: 2024 | G8: =IF(AND(D8>5, E8>1000), "Popular", "Not Popular") -> Popular | H8: =IF(OR(ISNUMBER(SEARCH("Action", C8)), ISNUMBER(SEARCH("Drama", C8))), "Action or Drama", IF(OR(ISNUMBER(SEARCH("Horror", C8)), ISNUMBER(SEARCH("Thriller", C8))), "Horror or Thriller", "Other")) -> Horror or Thriller | I8: =IF(NOT(ISNUMBER(SEARCH("Comedy", C8))), "Not Comedy", "Comedy") -> Not Comedy | J8: =IF(F8>2020, "Recent", "Old") -> Recent
A9: tt1340094 | B9: The Crow | C9: Action, Crime, Fantasy | D9: 4.7 | E9: 24427 | F9: 2024 | G9: =IF(AND(D9>5, E9>1000), "Popular", "Not Popular") -> Not Popular | H9: =IF(OR(ISNUMBER(SEARCH("Action", C9)), ISNUMBER(SEARCH("Drama", C9))), "Action or Drama", IF(OR(ISNUMBER(SEARCH("Horror", C9)), ISNUMBER(SEARCH("Thriller", C9))), "Horror or Thriller", "Other")) -> Action or Drama | I9: =IF(NOT(ISNUMBER(SEARCH("Comedy", C9))), "Not Comedy", "Comedy") -> Not Comedy | J9: =IF(F9>2020, "Recent", "Old") -> Recent
A10: tt30007864 | B10: The American Society of Magical Negroes | C10: Comedy, Fantasy | D10: 3.6 | E10: 10937 | F10: 2024 | G10: =IF(AND(D10>5, E10>1000), "Popular", "Not Popular") -> Not Popular | H10: =IF(OR(ISNUMBER(SEARCH("Action", C10)), ISNUMBER(SEARCH("Drama", C10))), "Action or Drama", IF(OR(ISNUMBER(SEARCH("Horror", C10)), ISNUMBER(SEARCH("Thriller", C10))), "Horror or Thriller", "Other")) -> Other | I10: =IF(NOT(ISNUMBER(SEARCH("Comedy", C10))), "Not Comedy", "Comedy") -> Comedy | J10: =IF(F10>2020, "Recent", "Old") -> Recent
A11: tt12262202 | B11: The Acolyte | C11: Action, Adventure, Drama | D11: 4.1 | E11: 124735 | F11: 2024 | G11: =IF(AND(D11>5, E11>1000), "Popular", "Not Popular") -> Not Popular | H11: =IF(OR(ISNUMBER(SEARCH("Action", C11)), ISNUMBER(SEARCH("Drama", C11))), "Action or Drama", IF(OR(ISNUMBER(SEARCH("Horror", C11)), ISNUMBER(SEARCH("Thriller", C11))), "Horror or Thriller", "Other")) -> Action or Drama | I11: =IF(NOT(ISNUMBER(SEARCH("Comedy", C11))), "Not Comedy", "Comedy") -> Not Comedy | J11: =IF(F11>2020, "Recent", "Old") -> Recent
A12: tt15387054 | B12: Teach/Corrupt | C12: Action, Adventure, Drama | D12: 5.1 | E12: 12964 | F12: 2024 | G12: =IF(AND(D12>5, E12>1000), "Popular", "Not Popular") -> Popular | H12: =IF(OR(ISNUMBER(SEARCH("Action", C12)), ISNUMBER(SEARCH("Drama", C12))), "Action or Drama", IF(OR(ISNUMBER(SEARCH("Horror", C12)), ISNUMBER(SEARCH("Thriller", C12))), "Horror or Thriller", "Other")) -> Action or Drama | I12: =IF(NOT(ISNUMBER(SEARCH("Comedy", C12))), "Not Comedy", "Comedy") -> Not Comedy | J12: =IF(F12>2020, "Recent", "Old") -> Recent
A13: tt14088510 | B13: Tarot | C13: Horror | D13: 4.8 | E13: 25522 | F13: 2024 | G13: =IF(AND(D13>5, E13>1000), "Popular", "Not Popular") -> Not Popular | H13: =IF(OR(ISNUMBER(SEARCH("Action", C13)), ISNUMBER(SEARCH("Drama", C13))), "Action or Drama", IF(OR(ISNUMBER(SEARCH("Horror", C13)), ISNUMBER(SEARCH("Thriller", C13))), "Horror or Thriller", "Other")) -> Horror or Thriller | I13: =IF(NOT(ISNUMBER(SEARCH("Comedy", C13))), "Not Comedy", "Comedy") -> Not Comedy | J13: =IF(F13>2020, "Recent", "Old") -> Recent
A14: tt15387022 | B14: Revenge/Justice | C14: Action, Adventure, Drama | D14: 5.1 | E14: 23343 | F14: 2024 | G14: =IF(AND(D14>5, E14>1000), "Popular", "Not Popular") -> Popular | H14: =IF(OR(ISNUMBER(SEARCH("Action", C14)), ISNUMBER(SEARCH("Drama", C14))), "Action or Drama", IF(OR(ISNUMBER(SEARCH("Horror", C14)), ISNUMBER(SEARCH("Thriller", C14))), "Horror or Thriller", "Other")) -> Action or Drama | I14: =IF(NOT(ISNUMBER(SEARCH("Comedy", C14))), "Not Comedy", "Comedy") -> Not Comedy | J14: =IF(F14>2020, "Recent", "Old") -> Recent
A15: tt19857862 | B15: Now or Never! | C15: Adventure, Biography, Drama | D15: 2 | E15: 16400 | F15: 2024 | G15: =IF(AND(D15>5, E15>1000), "Popular", "Not Popular") -> Not Popular | H15: =IF(OR(ISNUMBER(SEARCH("Action", C15)), ISNUMBER(SEARCH("Drama", C15))), "Action or Drama", IF(OR(ISNUMBER(SEARCH("Horror", C15)), ISNUMBER(SEARCH("Thriller", C15))), "Horror or Thriller", "Other")) -> Action or Drama | I15: =IF(NOT(ISNUMBER(SEARCH("Comedy", C15))), "Not Comedy", "Comedy") -> Not Comedy | J15: =IF(F15>2020, "Recent", "Old") -> Recent
A16: tt9682428 | B16: Night Swim | C16: Horror, Thriller | D16: 4.7 | E16: 25006 | F16: 2024 | G16: =IF(AND(D16>5, E16>1000), "Popular", "Not Popular") -> Not Popular | H16: =IF(OR(ISNUMBER(SEARCH("Action", C16)), ISNUMBER(SEARCH("Drama", C16))), "Action or Drama", IF(OR(ISNUMBER(SEARCH("Horror", C16)), ISNUMBER(SEARCH("Thriller", C16))), "Horror or Thriller", "Other")) -> Horror or Thriller | I16: =IF(NOT(ISNUMBER(SEARCH("Comedy", C16))), "Not Comedy", "Comedy") -> Not Comedy | J16: =IF(F16>2020, "Recent", "Old") -> Recent
A17: tt26926267 | B17: Mother of the Bride | C17: Comedy, Drama, Romance | D17: 4.8 | E17: 15187 | F17: 2024 | G17: =IF(AND(D17>5, E17>1000), "Popular", "Not Popular") -> Not Popular | H17: =IF(OR(ISNUMBER(SEARCH("Action", C17)), ISNUMBER(SEARCH("Drama", C17))), "Action or Drama", IF(OR(ISNUMBER(SEARCH("Horror", C17)), ISNUMBER(SEARCH("Thriller", C17))), "Horror or Thriller", "Other")) -> Action or Drama | I17: =IF(NOT(ISNUMBER(SEARCH("Comedy", C17))), "Not Comedy", "Comedy") -> Comedy | J17: =IF(F17>2020, "Recent", "Old") -> Recent
A18: tt10128846 | B18: Megalopolis | C18: Drama, Fantasy, Sci-Fi | D18: 5.1 | E18: 17457 | F18: 2024 | G18: =IF(AND(D18>5, E18>1000), "Popular", "Not Popular") -> Popular | H18: =IF(OR(ISNUMBER(SEARCH("Action", C18)), ISNUMBER(SEARCH("Drama", C18))), "Action or Drama", IF(OR(ISNUMBER(SEARCH("Horror", C18)), ISNUMBER(SEARCH("Thriller", C18))), "Horror or Thriller", "Other")) -> Action or Drama | I18: =IF(NOT(ISNUMBER(SEARCH("Comedy", C18))), "Not Comedy", "Comedy") -> Not Comedy | J18: =IF(F18>2020, "Recent", "Old") -> Recent
... A196: tt13423846 | B196: 321 Action | C196: Drama | D196: 1 | E196: 10215 | F196: 2020 | G196: =IF(AND(D196>5, E196>1000), "Popular", "Not Popular") -> Not Popular | H196: =IF(OR(ISNUMBER(SEARCH("Action", C196)), ISNUMBER(SEARCH("Drama", C196))), "Action or Drama", IF(OR(ISNUMBER(SEARCH("Horror", C196)), ISNUMBER(SEARCH("Thriller", C196))), "Horror or Thriller", "Other")) -> Action or Drama | I196: =IF(NOT(ISNUMBER(SEARCH("Comedy", C196))), "Not Comedy", "Comedy") -> Not Comedy | J196: =IF(F196>2020, "Recent", "Old") -> Old
A197: tt1918734 | B197: 2067 | C197: Mystery, Sci-Fi | D197: 4.9 | E197: 12090 | F197: 2020 | G197: =IF(AND(D197>5, E197>1000), "Popular", "Not Popular") -> Not Popular | H197: =IF(OR(ISNUMBER(SEARCH("Action", C197)), ISNUMBER(SEARCH("Drama", C197))), "Action or Drama", IF(OR(ISNUMBER(SEARCH("Horror", C197)), ISNUMBER(SEARCH("Thriller", C197))), "Horror or Thriller", "Other")) -> Other | I197: =IF(NOT(ISNUMBER(SEARCH("Comedy", C197))), "Not Comedy", "Comedy") -> Not Comedy | J197: =IF(F197>2020, "Recent", "Old") -> Old
A198: tt5913798 | B198: Wounds | C198: Drama, Horror, Mystery | D198: 4.1 | E198: 22267 | F198: 2019 | G198: =IF(AND(D198>5, E198>1000), "Popular", "Not Popular") -> Not Popular | H198: =IF(OR(ISNUMBER(SEARCH("Action", C198)), ISNUMBER(SEARCH("Drama", C198))), "Action or Drama", IF(OR(ISNUMBER(SEARCH("Horror", C198)), ISNUMBER(SEARCH("Thriller", C198))), "Horror or Thriller", "Other")) -> Action or Drama | I198: =IF(NOT(ISNUMBER(SEARCH("Comedy", C198))), "Not Comedy", "Comedy") -> Not Comedy | J198: =IF(F198>2020, "Recent", "Old") -> Old
A199: tt9625664 | B199: Trauma Center | C199: Action, Thriller | D199: 4 | E199: 12059 | F199: 2019 | G199: =IF(AND(D199>5, E199>1000), "Popular", "Not Popular") -> Not Popular | H199: =IF(OR(ISNUMBER(SEARCH("Action", C199)), ISNUMBER(SEARCH("Drama", C199))), "Action or Drama", IF(OR(ISNUMBER(SEARCH("Horror", C199)), ISNUMBER(SEARCH("Thriller", C199))), "Horror or Thriller", "Other")) -> Action or Drama | I199: =IF(NOT(ISNUMBER(SEARCH("Comedy", C199))), "Not Comedy", "Comedy") -> Not Comedy | J199: =IF(F199>2020, "Recent", "Old") -> Old
A200: tt5862166 | B200: The Poison Rose | C200: Crime, Mystery, Thriller | D200: 4.8 | E200: 11449 | F200: 2019 | G200: =IF(AND(D200>5, E200>1000), "Popular", "Not Popular") -> Not Popular | H200: =IF(OR(ISNUMBER(SEARCH("Action", C200)), ISNUMBER(SEARCH("Drama", C200))), "Action or Drama", IF(OR(ISNUMBER(SEARCH("Horror", C200)), ISNUMBER(SEARCH("Thriller", C200))), "Horror or Thriller", "Other")) -> Horror or Thriller | I200: =IF(NOT(ISNUMBER(SEARCH("Comedy", C200))), "Not Comedy", "Comedy") -> Not Comedy | J200: =IF(F200>2020, "Recent", "Old") -> Old
A201: tt4157728 | B201: The Last Boy | C201: Fantasy, Mystery, Sci-Fi | D201: 4.8 | E201: 10405 | F201: 2019 | G201: =IF(AND(D201>5, E201>1000), "Popular", "Not Popular") -> Not Popular | H201: =IF(OR(ISNUMBER(SEARCH("Action", C201)), ISNUMBER(SEARCH("Drama", C201))), "Action or Drama", IF(OR(ISNUMBER(SEARCH("Horror", C201)), ISNUMBER(SEARCH("Thriller", C201))), "Horror or Thriller", "Other")) -> Other | I201: =IF(NOT(ISNUMBER(SEARCH("Comedy", C201))), "Not Comedy", "Comedy") -> Not Comedy | J201: =IF(F201>2020, "Recent", "Old") -> Old
A202: tt6027920 | B202: The Iron Throne | C202: Action, Adventure, Drama | D202: 4 | E202: 267936 | F202: 2019 | G202: =IF(AND(D202>5, E202>1000), "Popular", "Not Popular") -> Not Popular | H202: =IF(OR(ISNUMBER(SEARCH("Action", C202)), ISNUMBER(SEARCH("Drama", C202))), "Action or Drama", IF(OR(ISNUMBER(SEARCH("Horror", C202)), ISNUMBER(SEARCH("Thriller", C202))), "Horror or Thriller", "Other")) -> Action or Drama | I202: =IF(NOT(ISNUMBER(SEARCH("Comedy", C202))), "Not Comedy", "Comedy") -> Not Comedy | J202: =IF(F202>2020, "Recent", "Old") -> Old
A203: tt9067020 | B203: The I-Land | C203: Adventure, Drama, Mystery | D203: 4.7 | E203: 19875 | F203: 2019 | G203: =IF(AND(D203>5, E203>1000), "Popular", "Not Popular") -> Not Popular | H203: =IF(OR(ISNUMBER(SEARCH("Action", C203)), ISNUMBER(SEARCH("Drama", C203))), "Action or Drama", IF(OR(ISNUMBER(SEARCH("Horror", C203)), ISNUMBER(SEARCH("Thriller", C203))), "Horror or Thriller", "Other")) -> Action or Drama | I203: =IF(NOT(ISNUMBER(SEARCH("Comedy", C203))), "Not Comedy", "Comedy") -> Not Comedy | J203: =IF(F203>2020, "Recent", "Old") -> Old
A204: tt3612126 | B204: The Grudge | C204: Fantasy, Horror | D204: 4.4 | E204: 30284 | F204: 2019 | G204: =IF(AND(D204>5, E204>1000), "Popular", "Not Popular") -> Not Popular | H204: =IF(OR(ISNUMBER(SEARCH("Action", C204)), ISNUMBER(SEARCH("Drama", C204))), "Action or Drama", IF(OR(ISNUMBER(SEARCH("Horror", C204)), ISNUMBER(SEARCH("Thriller", C204))), "Horror or Thriller", "Other")) -> Horror or Thriller | I204: =IF(NOT(ISNUMBER(SEARCH("Comedy", C204))), "Not Comedy", "Comedy") -> Not Comedy | J204: =IF(F204>2020, "Recent", "Old") -> Old
A205: tt7869070 | B205: The Fanatic | C205: Crime, Drama, Horror | D205: 4.1 | E205: 12749 | F205: 2019 | G205: =IF(AND(D205>5, E205>1000), "Popular", "Not Popular") -> Not Popular | H205: =IF(OR(ISNUMBER(SEARCH("Action", C205)), ISNUMBER(SEARCH("Drama", C205))), "Action or Drama", IF(OR(ISNUMBER(SEARCH("Horror", C205)), ISNUMBER(SEARCH("Thriller", C205))), "Horror or Thriller", "Other")) -> Action or Drama | I205: =IF(NOT(ISNUMBER(SEARCH("Comedy", C205))), "Not Comedy", "Comedy") -> Not Comedy | J205: =IF(F205>2020, "Recent", "Old") -> Old
A206: tt8075016 | B206: The Courier | C206: Action, Crime, Drama | D206: 4.8 | E206: 11849 | F206: 2019 | G206: =IF(AND(D206>5, E206>1000), "Popular", "Not Popular") -> Not Popular | H206: =IF(OR(ISNUMBER(SEARCH("Action", C206)), ISNUMBER(SEARCH("Drama", C206))), "Action or Drama", IF(OR(ISNUMBER(SEARCH("Horror", C206)), ISNUMBER(SEARCH("Thriller", C206))), "Horror or Thriller", "Other")) -> Action or Drama | I206: =IF(NOT(ISNUMBER(SEARCH("Comedy", C206))), "Not Comedy", "Comedy") -> Not Comedy | J206: =IF(F206>2020, "Recent", "Old") -> Old
A207: tt7255568 | B207: Student of the Year 2 | C207: Action, Comedy, Drama | D207: 2.2 | E207: 22954 | F207: 2019 | G207: =IF(AND(D207>5, E207>1000), "Popular", "Not Popular") -> Not Popular | H207: =IF(OR(ISNUMBER(SEARCH("Action", C207)), ISNUMBER(SEARCH("Drama", C207))), "Action or Drama", IF(OR(ISNUMBER(SEARCH("Horror", C207)), ISNUMBER(SEARCH("Thriller", C207))), "Horror or Thriller", "Other")) -> Action or Drama | I207: =IF(NOT(ISNUMBER(SEARCH("Comedy", C207))), "Not Comedy", "Comedy") -> Comedy | J207: =IF(F207>2020, "Recent", "Old") -> Old
A208: tt9419834 | B208: Secret Obsession | C208: Crime, Drama, Mystery | D208: 4.5 | E208: 24829 | F208: 2019 | G208: =IF(AND(D208>5, E208>1000), "Popular", "Not Popular") -> Not Popular | H208: =IF(OR(ISNUMBER(SEARCH("Action", C208)), ISNUMBER(SEARCH("Drama", C208))), "Action or Drama", IF(OR(ISNUMBER(SEARCH("Horror", C208)), ISNUMBER(SEARCH("Thriller", C208))), "Horror or Thriller", "Other")) -> Action or Drama | I208: =IF(NOT(ISNUMBER(SEARCH("Comedy", C208))), "Not Comedy", "Comedy") -> Not Comedy | J208: =IF(F208>2020, "Recent", "Old") -> Old
A209: tt6836936 | B209: Saaho | C209: Action, Thriller | D209: 5.1 | E209: 24451 | F209: 2019 | G209: =IF(AND(D209>5, E209>1000), "Popular", "Not Popular") -> Popular | H209: =IF(OR(ISNUMBER(SEARCH("Action", C209)), ISNUMBER(SEARCH("Drama", C209))), "Action or Drama", IF(OR(ISNUMBER(SEARCH("Horror", C209)), ISNUMBER(SEARCH("Thriller", C209))), "Horror or Thriller", "Other")) -> Action or Drama | I209: =IF(NOT(ISNUMBER(SEARCH("Comedy", C209))), "Not Comedy", "Comedy") -> Not Comedy | J209: =IF(F209>2020, "Recent", "Old") -> Old
... A338: tt4059702 | B338: AmeriGeddon | C338: Action, Adventure, Drama | D338: 3.8 | E338: 13397 | F338: 2016 | G338: =IF(AND(D338>5, E338>1000), "Popular", "Not Popular") -> Not Popular | H338: =IF(OR(ISNUMBER(SEARCH("Action", C338)), ISNUMBER(SEARCH("Drama", C338))), "Action or Drama", IF(OR(ISNUMBER(SEARCH("Horror", C338)), ISNUMBER(SEARCH("Thriller", C338))), "Horror or Thriller", "Other")) -> Action or Drama | I338: =IF(NOT(ISNUMBER(SEARCH("Comedy", C338))), "Not Comedy", "Comedy") -> Not Comedy | J338: =IF(F338>2020, "Recent", "Old") -> Old
A339: tt3835080 | B339: 31 | C339: Horror, Thriller | D339: 5.1 | E339: 23633 | F339: 2016 | G339: =IF(AND(D339>5, E339>1000), "Popular", "Not Popular") -> Popular | H339: =IF(OR(ISNUMBER(SEARCH("Action", C339)), ISNUMBER(SEARCH("Drama", C339))), "Action or Drama", IF(OR(ISNUMBER(SEARCH("Horror", C339)), ISNUMBER(SEARCH("Thriller", C339))), "Horror or Thriller", "Other")) -> Horror or Thriller | I339: =IF(NOT(ISNUMBER(SEARCH("Comedy", C339))), "Not Comedy", "Comedy") -> Not Comedy | J339: =IF(F339>2020, "Recent", "Old") -> Old
A340: tt3480796 | B340: Vice | C340: Action, Sci-Fi, Thriller | D340: 4.2 | E340: 17210 | F340: 2015 | G340: =IF(AND(D340>5, E340>1000), "Popular", "Not Popular") -> Not Popular | H340: =IF(OR(ISNUMBER(SEARCH("Action", C340)), ISNUMBER(SEARCH("Drama", C340))), "Action or Drama", IF(OR(ISNUMBER(SEARCH("Horror", C340)), ISNUMBER(SEARCH("Thriller", C340))), "Horror or Thriller", "Other")) -> Action or Drama | I340: =IF(NOT(ISNUMBER(SEARCH("Comedy", C340))), "Not Comedy", "Comedy") -> Not Comedy | J340: =IF(F340>2020, "Recent", "Old") -> Old
A341: tt1524575 | B341: The Vatican Tapes | C341: Horror, Thriller | D341: 4.7 | E341: 19462 | F341: 2015 | G341: =IF(AND(D341>5, E341>1000), "Popular", "Not Popular") -> Not Popular | H341: =IF(OR(ISNUMBER(SEARCH("Action", C341)), ISNUMBER(SEARCH("Drama", C341))), "Action or Drama", IF(OR(ISNUMBER(SEARCH("Horror", C341)), ISNUMBER(SEARCH("Thriller", C341))), "Horror or Thriller", "Other")) -> Horror or Thriller | I341: =IF(NOT(ISNUMBER(SEARCH("Comedy", C341))), "Not Comedy", "Comedy") -> Not Comedy | J341: =IF(F341>2020, "Recent", "Old") -> Old
A342: tt2938956 | B342: The Transporter Refueled | C342: Action, Thriller | D342: 5.2 | E342: 45631 | F342: 2015 | G342: =IF(AND(D342>5, E342>1000), "Popular", "Not Popular") -> Popular | H342: =IF(OR(ISNUMBER(SEARCH("Action", C342)), ISNUMBER(SEARCH("Drama", C342))), "Action or Drama", IF(OR(ISNUMBER(SEARCH("Horror", C342)), ISNUMBER(SEARCH("Thriller", C342))), "Horror or Thriller", "Other")) -> Action or Drama | I342: =IF(NOT(ISNUMBER(SEARCH("Comedy", C342))), "Not Comedy", "Comedy") -> Not Comedy | J342: =IF(F342>2020, "Recent", "Old") -> Old
A343: tt2479478 | B343: The Ridiculous 6 | C343: Action, Adventure, Comedy | D343: 4.9 | E343: 54734 | F343: 2015 | G343: =IF(AND(D343>5, E343>1000), "Popular", "Not Popular") -> Not Popular | H343: =IF(OR(ISNUMBER(SEARCH("Action", C343)), ISNUMBER(SEARCH("Drama", C343))), "Action or Drama", IF(OR(ISNUMBER(SEARCH("Horror", C343)), ISNUMBER(SEARCH("Thriller", C343))), "Horror or Thriller", "Other")) -> Action or Drama | I343: =IF(NOT(ISNUMBER(SEARCH("Comedy", C343))), "Not Comedy", "Comedy") -> Comedy | J343: =IF(F343>2020, "Recent", "Old") -> Old
A344: tt2918436 | B344: The Lazarus Effect | C344: Horror, Mystery, Sci-Fi | D344: 5.2 | E344: 46863 | F344: 2015 | G344: =IF(AND(D344>5, E344>1000), "Popular", "Not Popular") -> Popular | H344: =IF(OR(ISNUMBER(SEARCH("Action", C344)), ISNUMBER(SEARCH("Drama", C344))), "Action or Drama", IF(OR(ISNUMBER(SEARCH("Horror", C344)), ISNUMBER(SEARCH("Thriller", C344))), "Horror or Thriller", "Other")) -> Horror or Thriller | I344: =IF(NOT(ISNUMBER(SEARCH("Comedy", C344))), "Not Comedy", "Comedy") -> Not Comedy | J344: =IF(F344>2020, "Recent", "Old") -> Old
A345: tt1883367 | B345: The Human Centipede III (Final Sequence) | C345: Comedy, Horror | D345: 2.7 | E345: 20548 | F345: 2015 | G345: =IF(AND(D345>5, E345>1000), "Popular", "Not Popular") -> Not Popular | H345: =IF(OR(ISNUMBER(SEARCH("Action", C345)), ISNUMBER(SEARCH("Drama", C345))), "Action or Drama", IF(OR(ISNUMBER(SEARCH("Horror", C345)), ISNUMBER(SEARCH("Thriller", C345))), "Horror or Thriller", "Other")) -> Horror or Thriller | I345: =IF(NOT(ISNUMBER(SEARCH("Comedy", C345))), "Not Comedy", "Comedy") -> Comedy | J345: =IF(F345>2020, "Recent", "Old") -> Old
...

Sheet Chapter - 5
A1: 1) Using Vlookup to get the Genre and Release Year based on Id. 2) Sum Of Votes Per Release Year based on Genre. | L1: Which Genre Got Highest Votes Among all the Release Years?
A2: id | B2: Genre | C2: Release year(2000-2024) | D2: Sum Of Votes PerYear Based on Genre | F2: Top7 Titles in 2024 having highest votes | L2: Genres | M2: Total Votes for all Release years
A3: tt0192731 | B3: =VLOOKUP(A3, 'Raw data'!A2:F1001,3,FALSE) -> Horror, Mystery | C3: =VLOOKUP(A3,'Raw data'!A2:F1001,6,FALSE) -> 2000 | D3: =SUMIFS('Raw data'!E2:E1001, 'Raw data'!C2:C1001, B3, 'Raw data'!F2:F1001, C3) -> 19287 | F3: Title | G3: NumofVotes | H3: Genre | I3: AvgRating | L3: {=_xlfn.UNIQUE('Raw data'!C2:C1001)} -> Drama, Romance, Thriller | M3: =SUMIFS('Raw data'!E:E, 'Raw data'!C:C, L3) -> 407734
A4: tt0265087 | B4: =VLOOKUP(A4, 'Raw data'!A3:F1002,3,FALSE) -> Adventure, Comedy, Fantasy | C4: =VLOOKUP(A4,'Raw data'!A3:F1002,6,FALSE) -> 2001 | D4: =SUMIFS('Raw data'!E3:E1002, 'Raw data'!C3:C1002, B4, 'Raw data'!F3:F1002, C4) -> 43983 | F4: =INDEX('Raw data'!B2:B1001, MATCH(G4, 'Raw data'!E2:E1001, 0)) -> The Acolyte | G4: {=LARGE(IF('Raw data'!F2:F1001=2024, 'Raw data'!E2:E1001), 1)} -> 124735 | H4: =INDEX('Raw data'!C2:C1001, MATCH(F4, 'Raw data'!B2:B1001, 0)) -> Action, Adventure, Drama | I4: =INDEX('Raw data'!D2:D1001, MATCH(F4, 'Raw data'!B2:B1001, 0)) -> 4.1 | L4: Adventure, Drama, Fantasy | M4: =SUMIFS('Raw data'!E:E, 'Raw data'!C:C, L4) -> 563363
A5: tt0283632 | B5: =VLOOKUP(A5, 'Raw data'!A4:F1003,3,FALSE) -> Horror, Mystery, Thriller | C5: =VLOOKUP(A5,'Raw data'!A4:F1003,6,FALSE) -> 2002 | D5: =SUMIFS('Raw data'!E4:E1003, 'Raw data'!C4:C1003, B5, 'Raw data'!F4:F1003, C5) -> 29096 | F5: =INDEX('Raw data'!B3:B1002, MATCH(G5, 'Raw data'!E3:E1002, 0)) -> Madame Web | G5: {=LARGE(IF('Raw data'!F3:F1002=2024, 'Raw data'!E3:E1002), 2)} -> 91349 | H5: =INDEX('Raw data'!C3:C1002, MATCH(F5, 'Raw data'!B3:B1002, 0)) -> Action, Adventure, Sci-Fi | I5: =INDEX('Raw data'!D3:D1002, MATCH(F5, 'Raw data'!B3:B1002, 0)) -> 4 | L5: Action, Sci-Fi | M5: =SUMIFS('Raw data'!E:E, 'Raw data'!C:C, L5) -> 464662
A6: tt0313911 | B6: =VLOOKUP(A6, 'Raw data'!A5:F1004,3,FALSE) -> Action, Adventure, Comedy | C6: =VLOOKUP(A6,'Raw data'!A5:F1004,6,FALSE) -> 2003 | D6: =SUMIFS('Raw data'!E5:E1004, 'Raw data'!C5:C1004, B6, 'Raw data'!F5:F1004, C6) -> 274028 | F6: =INDEX('Raw data'!B4:B1003, MATCH(G6, 'Raw data'!E4:E1003, 0)) -> Indian Police Force | G6: {=LARGE(IF('Raw data'!F4:F1003=2024, 'Raw data'!E4:E1003), 3)} -> 58338 | H6: =INDEX('Raw data'!C4:C1003, MATCH(F6, 'Raw data'!B4:B1003, 0)) -> Action, Crime, Drama | I6: =INDEX('Raw data'!D4:D1003, MATCH(F6, 'Raw data'!B4:B1003, 0)) -> 4.9 | L6: Action, Adventure, Drama | M6: =SUMIFS('Raw data'!E:E, 'Raw data'!C:C, L6) -> 1341014
A7: tt0365957 | B7: =VLOOKUP(A7, 'Raw data'!A6:F1005,3,FALSE) -> Drama, Music | C7: =VLOOKUP(A7,'Raw data'!A6:F1005,6,FALSE) -> 2004 | D7: =SUMIFS('Raw data'!E6:E1005, 'Raw data'!C6:C1005, B7, 'Raw data'!F6:F1005, C7) -> 28830 | F7: =INDEX('Raw data'!B5:B1004, MATCH(G7, 'Raw data'!E5:E1004, 0)) -> Bade Miyan Chote Miyan | G7: {=LARGE(IF('Raw data'!F5:F1004=2024, 'Raw data'!E5:E1004), 4)} -> 38451 | H7: =INDEX('Raw data'!C5:C1004, MATCH(F7, 'Raw data'!B5:B1004, 0)) -> Action, Adventure, Sci-Fi | I7: =INDEX('Raw data'!D5:D1004, MATCH(F7, 'Raw data'!B5:B1004, 0)) -> 3.9 | L7: Adventure, Drama, Sci-Fi | M7: =SUMIFS('Raw data'!E:E, 'Raw data'!C:C, L7) -> 277533
A8: tt0808146 | B8: =VLOOKUP(A8, 'Raw data'!A7:F1006,3,FALSE) -> Comedy | C8: =VLOOKUP(A8,'Raw data'!A7:F1006,6,FALSE) -> 2006 | D8: =SUMIFS('Raw data'!E7:E1006, 'Raw data'!C7:C1006, B8, 'Raw data'!F7:F1006, C8) -> 225590 | F8: =INDEX('Raw data'!B6:B1005, MATCH(G8, 'Raw data'!E6:E1005, 0)) -> Martin | G8: {=LARGE(IF('Raw data'!F6:F1005=2024, 'Raw data'!E6:E1005), 5)} -> 34529 | H8: =INDEX('Raw data'!C6:C1005, MATCH(F8, 'Raw data'!B6:B1005, 0)) -> Action, Drama, Thriller | I8: =INDEX('Raw data'!D6:D1005, MATCH(F8, 'Raw data'!B6:B1005, 0)) -> 4.5 | L8: Action, Thriller | M8: =SUMIFS('Raw data'!E:E, 'Raw data'!C:C, L8) -> 564710
A9: tt0785077 | B9: =VLOOKUP(A9, 'Raw data'!A8:F1007,3,FALSE) -> Comedy, Sport | C9: =VLOOKUP(A9,'Raw data'!A8:F1007,6,FALSE) -> 2007 | D9: =SUMIFS('Raw data'!E8:E1007, 'Raw data'!C8:C1007, B9, 'Raw data'!F8:F1007, C9) -> 42021 | F9: =INDEX('Raw data'!B7:B1006, MATCH(G9, 'Raw data'!E7:E1006, 0)) -> Under Paris | G9: {=LARGE(IF('Raw data'!F7:F1006=2024, 'Raw data'!E7:E1006), 6)} -> 32479 | H9: =INDEX('Raw data'!C7:C1006, MATCH(F9, 'Raw data'!B7:B1006, 0)) -> Action, Drama, Horror | I9: =INDEX('Raw data'!D7:D1006, MATCH(F9, 'Raw data'!B7:B1006, 0)) -> 5.2 | L9: Action, Adventure, Sci-Fi | M9: =SUMIFS('Raw data'!E:E, 'Raw data'!C:C, L9) -> 1574437
A10: tt0443649 | B10: =VLOOKUP(A10, 'Raw data'!A9:F1008,3,FALSE) -> Action, Adventure, Drama | C10: =VLOOKUP(A10,'Raw data'!A9:F1008,6,FALSE) -> 2008 | D10: =SUMIFS('Raw data'!E9:E1008, 'Raw data'!C9:C1008, B10, 'Raw data'!F9:F1008, C10) -> 136533 | F10: =INDEX('Raw data'!B8:B1007, MATCH(G10, 'Raw data'!E8:E1007, 0)) -> Borderlands | G10: {=LARGE(IF('Raw data'!F8:F1007=2024, 'Raw data'!E8:E1007), 7)} -> 31263 | H10: =INDEX('Raw data'!C8:C1007, MATCH(F10, 'Raw data'!B8:B1007, 0)) -> Action, Adventure, Comedy | I10: =INDEX('Raw data'!D8:D1007, MATCH(F10, 'Raw data'!B8:B1007, 0)) -> 4.6 | L10: Action, Adventure, Comedy | M10: =SUMIFS('Raw data'!E:E, 'Raw data'!C:C, L10) -> 1636625
A11: tt1045778 | B11: =VLOOKUP(A11, 'Raw data'!A10:F1009,3,FALSE) -> Comedy | C11: =VLOOKUP(A11,'Raw data'!A10:F1009,6,FALSE) -> 2009 | D11: =SUMIFS('Raw data'!E10:E1009, 'Raw data'!C10:C1009, B11, 'Raw data'!F10:F1009, C11) -> 190898 | L11: Action, Crime, Thriller | M11: =SUMIFS('Raw data'!E:E, 'Raw data'!C:C, L11) -> 518203
A12: tt1320304 | B12: =VLOOKUP(A12, 'Raw data'!A11:F1010,3,FALSE) -> Horror, Thriller | C12: =VLOOKUP(A12,'Raw data'!A11:F1010,6,FALSE) -> 2010 | D12: =SUMIFS('Raw data'!E11:E1010, 'Raw data'!C11:C1010, B12, 'Raw data'!F11:F1010, C12) -> 40360 | F12: Genre: Top 7 Largest Sum of Votes among All Release Years | L12: Action, Adventure, Family | M12: =SUMIFS('Raw data'!E:E, 'Raw data'!C:C, L12) -> 344294
A13: tt1788979 | B13: =VLOOKUP(A13, 'Raw data'!A12:F1011,3,FALSE) -> Crime, Thriller | C13: =VLOOKUP(A13,'Raw data'!A12:F1011,6,FALSE) -> 2011 | D13: =SUMIFS('Raw data'!E12:E1011, 'Raw data'!C12:C1011, B13, 'Raw data'!F12:F1011, C13) -> 34925 | F13: Genre | G13: Top 7 Vote Counts | L13: Action, Adventure, Fantasy | M13: =SUMIFS('Raw data'!E:E, 'Raw data'!C:C, L13) -> 845644
A14: tt2375779 | B14: =VLOOKUP(A14, 'Raw data'!A13:F1012,3,FALSE) -> Adventure, Horror | C14: =VLOOKUP(A14,'Raw data'!A13:F1012,6,FALSE) -> 2012 | D14: =SUMIFS('Raw data'!E13:E1012, 'Raw data'!C13:C1012, B14, 'Raw data'!F13:F1012, C14) -> 23717 | F14: =INDEX(L$3:L$196, MATCH(LARGE(M$3:M$196, 1), M$3:M$196, 0)) -> Comedy | G14: =LARGE(M$3:M$196, 1) -> 1719522 | L14: Action, Comedy, Sci-Fi | M14: =SUMIFS('Raw data'!E:E, 'Raw data'!C:C, L14) -> 339253
A15: tt1606378 | B15: =VLOOKUP(A15, 'Raw data'!A9:F1013,3,FALSE) -> Action, Thriller | C15: =VLOOKUP(A15,'Raw data'!A9:F1013,6,FALSE) -> 2013 | D15: =SUMIFS('Raw data'!E14:E1013, 'Raw data'!C14:C1013, B15, 'Raw data'!F14:F1013, C15) -> 25450 | F15: =INDEX(L$3:L$196, MATCH(LARGE(M$3:M$196, 2), M$3:M$196, 0)) -> Action, Adventure, Comedy | G15: =LARGE(M$3:M$196, 2) -> 1636625 | L15: Action, Adventure, Horror | M15: =SUMIFS('Raw data'!E:E, 'Raw data'!C:C, L15) -> 598575
A16: tt2784512 | B16: =VLOOKUP(A16, 'Raw data'!A15:F1014,3,FALSE) -> Comedy, Horror | C16: =VLOOKUP(A16,'Raw data'!A15:F1014,6,FALSE) -> 2014 | D16: =SUMIFS('Raw data'!E15:E1014, 'Raw data'!C15:C1014, B16, 'Raw data'!F15:F1014, C16) -> 21038 | F16: =INDEX(L$3:L$196, MATCH(LARGE(M$3:M$196, 3), M$3:M$196, 0)) -> Action, Adventure, Sci-Fi | G16: =LARGE(M$3:M$196, 3) -> 1574437 | L16: Action, Horror, Sci-Fi | M16: =SUMIFS('Raw data'!E:E, 'Raw data'!C:C, L16) -> 729929
A17: tt3774790 | B17: =VLOOKUP(A17, 'Raw data'!A16:F1015,3,FALSE) -> Mystery, Sci-Fi, Thriller | C17: =VLOOKUP(A17,'Raw data'!A16:F1015,6,FALSE) -> 2015 | D17: =SUMIFS('Raw data'!E16:E1015, 'Raw data'!C16:C1015, B17, 'Raw data'!F16:F1015, C17) -> 11349 | F17: =INDEX(L$3:L$196, MATCH(LARGE(M$3:M$196, 4), M$3:M$196, 0)) -> Horror, Mystery, Thriller | G17: =LARGE(M$3:M$196, 4) -> 1377044 | L17: Comedy | M17: =SUMIFS('Raw data'!E:E, 'Raw data'!C:C, L17) -> 1719522
A18: tt1608290 | B18: =VLOOKUP(A18, 'Raw data'!A17:F1016,3,FALSE) -> Action, Adventure, Comedy | C18: =VLOOKUP(A18,'Raw data'!A17:F1016,6,FALSE) -> 2016 | D18: =SUMIFS('Raw data'!E17:E1016, 'Raw data'!C17:C1016, B18, 'Raw data'!F17:F1016, C18) -> 77401 | F18: =INDEX(L$3:L$196, MATCH(LARGE(M$3:M$196, 5), M$3:M$196, 0)) -> Action, Adventure, Drama | G18: =LARGE(M$3:M$196, 5) -> 1341014 | L18: Action, Comedy, Crime | M18: =SUMIFS('Raw data'!E:E, 'Raw data'!C:C, L18) -> 882591
A19: tt1935897 | B19: =VLOOKUP(A19, 'Raw data'!A18:F1017,3,FALSE) -> Horror, Thriller | C19: =VLOOKUP(A19,'Raw data'!A18:F1017,6,FALSE) -> 2017 | D19: =SUMIFS('Raw data'!E18:E1017, 'Raw data'!C18:C1017, B19, 'Raw data'!F18:F1017, C19) -> 30154 | F19: =INDEX(L$3:L$196, MATCH(LARGE(M$3:M$196, 6), M$3:M$196, 0)) -> Horror, Thriller | G19: =LARGE(M$3:M$196, 6) -> 1085481 | L19: Action, Fantasy, Thriller | M19: =SUMIFS('Raw data'!E:E, 'Raw data'!C:C, L19) -> 128358
A20: tt5842616 | B20: =VLOOKUP(A20, 'Raw data'!A19:F1018,3,FALSE) -> Comedy | C20: =VLOOKUP(A20,'Raw data'!A19:F1018,6,FALSE) -> 2018 | D20: =SUMIFS('Raw data'!E19:E1018, 'Raw data'!C19:C1018, B20, 'Raw data'!F19:F1018, C20) -> 92272 | F20: =INDEX(L$3:L$196, MATCH(LARGE(M$3:M$196, 7), M$3:M$196, 0)) -> Adventure, Comedy, Family | G20: =LARGE(M$3:M$196, 7) -> 1013081 | L20: Action, Crime, Fantasy | M20: =SUMIFS('Raw data'!E:E, 'Raw data'!C:C, L20) -> 276390
A21: tt7329656 | B21: =VLOOKUP(A21, 'Raw data'!A20:F1019,3,FALSE) -> Adventure, Drama, Horror | C21: =VLOOKUP(A21,'Raw data'!A20:F1019,6,FALSE) -> 2019 | D21: =SUMIFS('Raw data'!E20:E1019, 'Raw data'!C20:C1019, B21, 'Raw data'!F20:F1019, C21) -> 31684 | L21: Comedy, Romance | M21: =SUMIFS('Raw data'!E:E, 'Raw data'!C:C, L21) -> 837880
A22: tt10600398 | B22: =VLOOKUP(A22, 'Raw data'!A21:F1020,3,FALSE) -> Action, Animation, Comedy | C22: =VLOOKUP(A22,'Raw data'!A21:F1020,6,FALSE) -> 2020 | D22: =SUMIFS('Raw data'!E21:E1020, 'Raw data'!C21:C1020, B22, 'Raw data'!F21:F1020, C22) -> 17665 | F22: Top 5 Genre Having highest Votes and Their Release Year | L22: Horror, Thriller | M22: =SUMIFS('Raw data'!E:E, 'Raw data'!C:C, L22) -> 1085481
A23: tt14878948 | B23: =VLOOKUP(A23, 'Raw data'!A22:F1021,3,FALSE) -> Action, Drama, War | C23: =VLOOKUP(A23,'Raw data'!A22:F1021,6,FALSE) -> 2021 | D23: =SUMIFS('Raw data'!E22:E1021, 'Raw data'!C22:C1021, B23, 'Raw data'!F22:F1021, C23) -> 20687 | F23: Genre | G23: Release Year | H23: Highest Vote Count | L23: Drama, Mystery, Romance | M23: =SUMIFS('Raw data'!E:E, 'Raw data'!C:C, L23) -> 248427
A24: tt13235822 | B24: =VLOOKUP(A24, 'Raw data'!A23:F1022,3,FALSE) -> Drama, Horror, Mystery | C24: =VLOOKUP(A24,'Raw data'!A23:F1022,6,FALSE) -> 2022 | D24: =SUMIFS('Raw data'!E23:E1022, 'Raw data'!C23:C1022, B24, 'Raw data'!F23:F1022, C24) -> 99277 | F24: =INDEX($B$2:$B$54, MATCH(H24, $D$2:$D$54, 0)) -> Action, Adventure, Comedy | G24: =INDEX($C$2:$C$54, MATCH(H24, $D$2:$D$54, 0)) -> 2003 | H24: =LARGE($D$2:$D$54, 1) -> 274028 | L24: Drama, Music | M24: =SUMIFS('Raw data'!E:E, 'Raw data'!C:C, L24) -> 141466
A25: tt12915716 | B25: =VLOOKUP(A25, 'Raw data'!A24:F1023,3,FALSE) -> Action, Adventure, Drama | C25: =VLOOKUP(A25,'Raw data'!A24:F1023,6,FALSE) -> 2023 | D25: =SUMIFS('Raw data'!E24:E1023, 'Raw data'!C24:C1023, B25, 'Raw data'!F24:F1023, C25) -> 172067 | F25: =INDEX($B$2:$B$54, MATCH(H25, $D$2:$D$54, 0)) -> Comedy | G25: =INDEX($C$2:$C$54, MATCH(H25, $D$2:$D$54, 0)) -> 2006 | H25: =LARGE($D$2:$D$54, 2) -> 225590 | L25: Comedy, Fantasy | M25: =SUMIFS('Raw data'!E:E, 'Raw data'!C:C, L25) -> 165658
A26: tt13964390 | B26: =VLOOKUP(A26, 'Raw data'!A25:F1024,3,FALSE) -> Action, Drama, Horror | C26: =VLOOKUP(A26,'Raw data'!A25:F1024,6,FALSE) -> 2024 | D26: =SUMIFS('Raw data'!E25:E1024, 'Raw data'!C25:C1024, B26, 'Raw data'!F25:F1024, C26) -> 32479 | F26: =INDEX($B$2:$B$54, MATCH(H26, $D$2:$D$54, 0)) -> Comedy | G26: =INDEX($C$2:$C$54, MATCH(H26, $D$2:$D$54, 0)) -> 2009 | H26: =LARGE($D$2:$D$54, 3) -> 190898 | L26: Adventure, Comedy, Fantasy | M26: =SUMIFS('Raw data'!E:E, 'Raw data'!C:C, L26) -> 206207
F27: =INDEX($B$2:$B$54, MATCH(H27, $D$2:$D$54, 0)) -> Action, Adventure, Drama | G27: =INDEX($C$2:$C$54, MATCH(H27, $D$2:$D$54, 0)) -> 2023 | H27: =LARGE($D$2:$D$54, 4) -> 172067 | L27: Crime, Drama, Horror | M27: =SUMIFS('Raw data'!E:E, 'Raw data'!C:C, L27) -> 149690
F28: =INDEX($B$2:$B$54, MATCH(H28, $D$2:$D$54, 0)) -> Action, Adventure, Drama | G28: =INDEX($C$2:$C$54, MATCH(H28, $D$2:$D$54, 0)) -> 2008 | H28: =LARGE($D$2:$D$54, 5) -> 136533 | L28: Crime, Thriller | M28: =SUMIFS('Raw data'!E:E, 'Raw data'!C:C, L28) -> 158658
L29: Drama, Romance | M29: =SUMIFS('Raw data'!E:E, 'Raw data'!C:C, L29) -> 324515
F30: Total Votes from 2021-24 based on Genre | L30: Action, Adventure, Crime | M30: =SUMIFS('Raw data'!E:E, 'Raw data'!C:C, L30) -> 375823
F31: Genre | G31: Total Votes In 2021 | H31: Total Votes In 2022 | I31: Total Votes In 2023 | J31: Total Votes In 2024 | L31: Action, Adventure, Thriller | M31: =SUMIFS('Raw data'!E:E, 'Raw data'!C:C, L31) -> 198737
F32: Comedy | G32: =SUMIFS('Raw data'!E2:E1001, 'Raw data'!F2:F1001,2021, 'Raw data'!C2:C1001, F32) -> 0 | H32: =SUMIFS('Raw data'!E2:E1001, 'Raw data'!F2:F1001, 2022, 'Raw data'!C2:C1001, F32) -> 71074 | I32: =SUMIFS('Raw data'!E2:E1001, 'Raw data'!F2:F1001, 2023, 'Raw data'!C2:C1001, F32) -> 0 | J32: =SUMIFS('Raw data'!E2:E1001, 'Raw data'!F2:F1001, 2024, 'Raw data'!C2:C1001, F32) -> 0 | L32: Adventure, Comedy, Family | M32: =SUMIFS('Raw data'!E:E, 'Raw data'!C:C, L32) -> 1013081
F33: Action, Adventure, Comedy | G33: =SUMIFS('Raw data'!E3:E1002, 'Raw data'!F3:F1002,2021, 'Raw data'!C3:C1002, F33) -> 60406 | H33: =SUMIFS('Raw data'!E3:E1002, 'Raw data'!F3:F1002, 2022, 'Raw data'!C3:C1002, F33) -> 208770 | I33: =SUMIFS('Raw data'!E3:E1002, 'Raw data'!F3:F1002, 2023, 'Raw data'!C3:C1002, F33) -> 0 | J33: =SUMIFS('Raw data'!E3:E1002, 'Raw data'!F3:F1002, 2024, 'Raw data'!C3:C1002, F33) -> 31263 | L33: Action, Drama | M33: =SUMIFS('Raw data'!E:E, 'Raw data'!C:C, L33) -> 176512
F34: Action, Adventure, Sci-Fi | G34: =SUMIFS('Raw data'!E4:E1003, 'Raw data'!F4:F1003,2021, 'Raw data'!C4:C1003, F34) -> 0 | H34: =SUMIFS('Raw data'!E4:E1003, 'Raw data'!F4:F1003, 2022, 'Raw data'!C4:C1003, F34) -> 103225 | I34: =SUMIFS('Raw data'!E4:E1003, 'Raw data'!F4:F1003, 2023, 'Raw data'!C4:C1003, F34) -> 0 | J34: =SUMIFS('Raw data'!E4:E1003, 'Raw data'!F4:F1003, 2024, 'Raw data'!C4:C1003, F34) -> 129800 | L34: Drama | M34: =SUMIFS('Raw data'!E:E, 'Raw data'!C:C, L34) -> 327340
F35: Horror, Mystery, Thriller | G35: =SUMIFS('Raw data'!E5:E1004, 'Raw data'!F5:F1004,2021, 'Raw data'!C5:C1004, F35) -> 91525 | H35: =SUMIFS('Raw data'!E5:E1004, 'Raw data'!F5:F1004, 2022, 'Raw data'!C5:C1004, F35) -> 15339 | I35: =SUMIFS('Raw data'!E5:E1004, 'Raw data'!F5:F1004, 2023, 'Raw data'!C5:C1004, F35) -> 0 | J35: =SUMIFS('Raw data'!E5:E1004, 'Raw data'!F5:F1004, 2024, 'Raw data'!C5:C1004, F35) -> 15023 | L35: Comedy, Sci-Fi | M35: =SUMIFS('Raw data'!E:E, 'Raw data'!C:C, L35) -> 173196
F36: Action, Adventure, Drama | G36: =SUMIFS('Raw data'!E6:E1005, 'Raw data'!F6:F1005,2021, 'Raw data'!C6:C1005, F36) -> 26968 | H36: =SUMIFS('Raw data'!E6:E1005, 'Raw data'!F6:F1005, 2022, 'Raw data'!C6:C1005, F36) -> 131192 | I36: =SUMIFS('Raw data'!E6:E1005, 'Raw data'!F6:F1005, 2023, 'Raw data'!C6:C1005, F36) -> 172067 | J36: =SUMIFS('Raw data'!E6:E1005, 'Raw data'!F6:F1005, 2024, 'Raw data'!C6:C1005, F36) -> 243324 | L36: Action, Sci-Fi, Thriller | M36: =SUMIFS('Raw data'!E:E, 'Raw data'!C:C, L36) -> 241930
F37: Horror, Thriller | G37: =SUMIFS('Raw data'!E7:E1006, 'Raw data'!F7:F1006,2021, 'Raw data'!C7:C1006, F37) -> 0 | H37: =SUMIFS('Raw data'!E7:E1006, 'Raw data'!F7:F1006, 2022, 'Raw data'!C7:C1006, F37) -> 10942 | I37: =SUMIFS('Raw data'!E7:E1006, 'Raw data'!F7:F1006, 2023, 'Raw data'!C7:C1006, F37) -> 0 | J37: =SUMIFS('Raw data'!E7:E1006, 'Raw data'!F7:F1006, 2024, 'Raw data'!C7:C1006, F37) -> 44373 | L37: Crime, Drama, Fantasy | M37: =SUMIFS('Raw data'!E:E, 'Raw data'!C:C, L37) -> 142545
F38: Adventure, Comedy, Family | G38: =SUMIFS('Raw data'!E8:E1007, 'Raw data'!F8:F1007,2021, 'Raw data'!C8:C1007, F38) -> 0 | H38: =SUMIFS('Raw data'!E8:E1007, 'Raw data'!F8:F1007, 2022, 'Raw data'!C8:C1007, F38) -> 0 | I38: =SUMIFS('Raw data'!E8:E1007, 'Raw data'!F8:F1007, 2023, 'Raw data'!C8:C1007, F38) -> 10876 | J38: =SUMIFS('Raw data'!E8:E1007, 'Raw data'!F8:F1007, 2024, 'Raw data'!C8:C1007, F38) -> 0 | L38: Horror | M38: =SUMIFS('Raw data'!E:E, 'Raw data'!C:C, L38) -> 652208
L39: Comedy, Family, Fantasy | M39: =SUMIFS('Raw data'!E:E, 'Raw data'!C:C, L39) -> 490679
L40: Documentary, Drama, History | M40: =SUMIFS('Raw data'!E:E, 'Raw data'!C:C, L40) -> 109008
...

Sheet Chapter-6
